Workbook

Sheet Instructions
A1: GA4 ANALYTICS REPORT — DATA PULL INSTRUCTIONS
A2: PE Portfolio HVAC Brands — 2024 vs 2025 & Jan '25 vs Jan '26 Comparison
A4: OVERVIEW
B5: This workbook contains one tab per brand plus a Summary tab that auto-calculates YoY changes.
B6: You will pull data from GA4 for 4 date ranges and paste it into each brand's tab.
B7: The Summary tab will auto-populate once all brand tabs are filled in.
B9: PURPOSE: Assess the efficacy of broadcast TV, targeted display, and OTT advertising
B10: across the portfolio by comparing website traffic, engagement, conversions, and traffic sources.
A12: DATE RANGES TO PULL
B13: Period | C13: Exact Date Range in GA4
B14: Period A: Full Year 2024 | C14: Jan 1, 2024 – Dec 31, 2024
B15: Period B: Full Year 2025 | C15: Jan 1, 2025 – Dec 31, 2025
B16: Period C: January 2025 | C16: Jan 1, 2025 – Jan 31, 2025
B17: Period D: January 2026 | C17: Jan 1, 2026 – Jan 31, 2026
A19: STEP-BY-STEP: PULLING DATA FROM GA4
B20: STEP 1: Open GA4 & Select the Brand Property
B21: Go to analytics.google.com
B22: Click the property selector (top-left dropdown) and choose the brand's GA4 property
B23: Verify you see the correct Account ID matching the brand tab in this workbook
B25: STEP 2: Pull Overview Metrics (Traffic, Engagement, Conversions)
B26: Navigate to: Reports → Life cycle → Acquisition → Overview
B27: Set the date range to Period A (Jan 1, 2024 – Dec 31, 2024)
B28: Note down: Users, New Users, Sessions from the overview cards
B30: Then navigate to: Reports → Life cycle → Engagement → Overview
B31: Note down: Engagement Rate, Avg. Session Duration, Events, Pageviews, Pages/Session
B33: Then navigate to: Reports → Life cycle → Engagement → Conversions (Key Events)
B34: Note down: Total conversions, User Conversion Rate, Session Conversion Rate
... B84: You can export this as CSV and paste values directly into the brand tabs
A86: BRAND LIST & GA4 ACCOUNT IDs
B87: Brand Name | C87: GA4 Account ID
B88: Anthony | C88: 266746707
B89: Anytime Plumbing, Heating & Cooling | C89: 48850300
B90: Apollo Home | C90: 11121287
B91: Arctic Air Conditioning | C91: 12778303
B92: Aztec Plumbing | C92: —
B93: Bell Brothers | C93: 262504860
B94: Black Hills Inc | C94: 26334622
B95: Campbell and Company | C95: 79041634
B96: Cassell Brothers | C96: 104694076
B97: Charles Stone Mechanical | C97: 282662324
...

Sheet Summary
A1: PORTFOLIO SUMMARY — ALL BRANDS COMPARISON
A2: Auto-populated from individual brand tabs | Yellow cells = enter data on brand tabs
A4: Total Users — ALL BRANDS
B5: Brand | C5: FY 2024 | D5: FY 2025 | E5: YoY Δ% | F5: Jan 2025 | G5: Jan 2026 | H5: Jan YoY Δ%
B6: Anthony | C6: =Anthony!C7 -> 0 | D6: =Anthony!D7 -> 0 | E6: =Anthony!E7 -> N/A | F6: =Anthony!F7 -> 0 | G6: =Anthony!G7 -> 0 | H6: =Anthony!H7 -> N/A
B7: Anytime Plumbing, Heating & Cooling | C7: ='Anytime PHC'!C7 -> 0 | D7: ='Anytime PHC'!D7 -> 0 | E7: ='Anytime PHC'!E7 -> N/A | F7: ='Anytime PHC'!F7 -> 0 | G7: ='Anytime PHC'!G7 -> 0 | H7: ='Anytime PHC'!H7 -> N/A
B8: Apollo Home | C8: ='Apollo Home'!C7 -> 0 | D8: ='Apollo Home'!D7 -> 0 | E8: ='Apollo Home'!E7 -> N/A | F8: ='Apollo Home'!F7 -> 0 | G8: ='Apollo Home'!G7 -> 0 | H8: ='Apollo Home'!H7 -> N/A
B9: Arctic Air Conditioning | C9: ='Arctic Air'!C7 -> 0 | D9: ='Arctic Air'!D7 -> 0 | E9: ='Arctic Air'!E7 -> N/A | F9: ='Arctic Air'!F7 -> 0 | G9: ='Arctic Air'!G7 -> 0 | H9: ='Arctic Air'!H7 -> N/A
B10: Aztec Plumbing | C10: ='Aztec Plumbing'!C7 -> 0 | D10: ='Aztec Plumbing'!D7 -> 0 | E10: ='Aztec Plumbing'!E7 -> N/A | F10: ='Aztec Plumbing'!F7 -> 0 | G10: ='Aztec Plumbing'!G7 -> 0 | H10: ='Aztec Plumbing'!H7 -> N/A
B11: Bell Brothers | C11: ='Bell Brothers'!C7 -> 0 | D11: ='Bell Brothers'!D7 -> 0 | E11: ='Bell Brothers'!E7 -> N/A | F11: ='Bell Brothers'!F7 -> 0 | G11: ='Bell Brothers'!G7 -> 0 | H11: ='Bell Brothers'!H7 -> N/A
B12: Black Hills Inc | C12: ='Black Hills'!C7 -> 0 | D12: ='Black Hills'!D7 -> 0 | E12: ='Black Hills'!E7 -> N/A | F12: ='Black Hills'!F7 -> 0 | G12: ='Black Hills'!G7 -> 0 | H12: ='Black Hills'!H7 -> N/A
B13: Campbell and Company | C13: ='Campbell & Co'!C7 -> 0 | D13: ='Campbell & Co'!D7 -> 0 | E13: ='Campbell & Co'!E7 -> N/A | F13: ='Campbell & Co'!F7 -> 0 | G13: ='Campbell & Co'!G7 -> 0 | H13: ='Campbell & Co'!H7 -> N/A
B14: Cassell Brothers | C14: ='Cassell Bros'!C7 -> 0 | D14: ='Cassell Bros'!D7 -> 0 | E14: ='Cassell Bros'!E7 -> N/A | F14: ='Cassell Bros'!F7 -> 0 | G14: ='Cassell Bros'!G7 -> 0 | H14: ='Cassell Bros'!H7 -> N/A
B15: Charles Stone Mechanical | C15: ='Charles Stone'!C7 -> 0 | D15: ='Charles Stone'!D7 -> 0 | E15: ='Charles Stone'!E7 -> N/A | F15: ='Charles Stone'!F7 -> 0 | G15: ='Charles Stone'!G7 -> 0 | H15: ='Charles Stone'!H7 -> N/A
B16: Dauenhauer Plumbing | C16: =Dauenhauer!C7 -> 0 | D16: =Dauenhauer!D7 -> 0 | E16: =Dauenhauer!E7 -> N/A | F16: =Dauenhauer!F7 -> 0 | G16: =Dauenhauer!G7 -> 0 | H16: =Dauenhauer!H7 -> N/A
B17: Fayette Heating & Air | C17: ='Fayette HA'!C7 -> 0 | D17: ='Fayette HA'!D7 -> 0 | E17: ='Fayette HA'!E7 -> N/A | F17: ='Fayette HA'!F7 -> 0 | G17: ='Fayette HA'!G7 -> 0 | H17: ='Fayette HA'!H7 -> N/A
B18: GAC Services | C18: ='GAC Services'!C7 -> 0 | D18: ='GAC Services'!D7 -> 0 | E18: ='GAC Services'!E7 -> N/A | F18: ='GAC Services'!F7 -> 0 | G18: ='GAC Services'!G7 -> 0 | H18: ='GAC Services'!H7 -> N/A
B19: Hunter Super Techs | C19: ='Hunter Super Techs'!C7 -> 0 | D19: ='Hunter Super Techs'!D7 -> 0 | E19: ='Hunter Super Techs'!E7 -> N/A | F19: ='Hunter Super Techs'!F7 -> 0 | G19: ='Hunter Super Techs'!G7 -> 0 | H19: ='Hunter Super Techs'!H7 -> N/A
B20: LimRic | C20: =LimRic!C7 -> 0 | D20: =LimRic!D7 -> 0 | E20: =LimRic!E7 -> N/A | F20: =LimRic!F7 -> 0 | G20: =LimRic!G7 -> 0 | H20: =LimRic!H7 -> N/A
B21: Reliable Power Systems | C21: ='Reliable Power'!C7 -> 0 | D21: ='Reliable Power'!D7 -> 0 | E21: ='Reliable Power'!E7 -> N/A | F21: ='Reliable Power'!F7 -> 0 | G21: ='Reliable Power'!G7 -> 0 | H21: ='Reliable Power'!H7 -> N/A
B22: Roth Home | C22: ='Roth Home'!C7 -> 0 | D22: ='Roth Home'!D7 -> 0 | E22: ='Roth Home'!E7 -> N/A | F22: ='Roth Home'!F7 -> 0 | G22: ='Roth Home'!G7 -> 0 | H22: ='Roth Home'!H7 -> N/A
B23: Schaal Plumbing, Heating & Cooling | C23: ='Schaal PHC'!C7 -> 0 | D23: ='Schaal PHC'!D7 -> 0 | E23: ='Schaal PHC'!E7 -> N/A | F23: ='Schaal PHC'!F7 -> 0 | G23: ='Schaal PHC'!G7 -> 0 | H23: ='Schaal PHC'!H7 -> N/A
B24: Sunny Service | C24: ='Sunny Service'!C7 -> 0 | D24: ='Sunny Service'!D7 -> 0 | E24: ='Sunny Service'!E7 -> N/A | F24: ='Sunny Service'!F7 -> 0 | G24: ='Sunny Service'!G7 -> 0 | H24: ='Sunny Service'!H7 -> N/A
B25: Webb HVAC | C25: ='Webb HVAC'!C7 -> 0 | D25: ='Webb HVAC'!D7 -> 0 | E25: ='Webb HVAC'!E7 -> N/A | F25: ='Webb HVAC'!F7 -> 0 | G25: ='Webb HVAC'!G7 -> 0 | H25: ='Webb HVAC'!H7 -> N/A
A27: New Users — ALL BRANDS
B28: Brand | C28: FY 2024 | D28: FY 2025 | E28: YoY Δ% | F28: Jan 2025 | G28: Jan 2026 | H28: Jan YoY Δ%
B29: Anthony | C29: =Anthony!C8 -> 0 | D29: =Anthony!D8 -> 0 | E29: =Anthony!E8 -> N/A | F29: =Anthony!F8 -> 0 | G29: =Anthony!G8 -> 0 | H29: =Anthony!H8 -> N/A
B30: Anytime Plumbing, Heating & Cooling | C30: ='Anytime PHC'!C8 -> 0 | D30: ='Anytime PHC'!D8 -> 0 | E30: ='Anytime PHC'!E8 -> N/A | F30: ='Anytime PHC'!F8 -> 0 | G30: ='Anytime PHC'!G8 -> 0 | H30: ='Anytime PHC'!H8 -> N/A
B31: Apollo Home | C31: ='Apollo Home'!C8 -> 0 | D31: ='Apollo Home'!D8 -> 0 | E31: ='Apollo Home'!E8 -> N/A | F31: ='Apollo Home'!F8 -> 0 | G31: ='Apollo Home'!G8 -> 0 | H31: ='Apollo Home'!H8 -> N/A
B32: Arctic Air Conditioning | C32: ='Arctic Air'!C8 -> 0 | D32: ='Arctic Air'!D8 -> 0 | E32: ='Arctic Air'!E8 -> N/A | F32: ='Arctic Air'!F8 -> 0 | G32: ='Arctic Air'!G8 -> 0 | H32: ='Arctic Air'!H8 -> N/A
B33: Aztec Plumbing | C33: ='Aztec Plumbing'!C8 -> 0 | D33: ='Aztec Plumbing'!D8 -> 0 | E33: ='Aztec Plumbing'!E8 -> N/A | F33: ='Aztec Plumbing'!F8 -> 0 | G33: ='Aztec Plumbing'!G8 -> 0 | H33: ='Aztec Plumbing'!H8 -> N/A
B34: Bell Brothers | C34: ='Bell Brothers'!C8 -> 0 | D34: ='Bell Brothers'!D8 -> 0 | E34: ='Bell Brothers'!E8 -> N/A | F34: ='Bell Brothers'!F8 -> 0 | G34: ='Bell Brothers'!G8 -> 0 | H34: ='Bell Brothers'!H8 -> N/A
B35: Black Hills Inc | C35: ='Black Hills'!C8 -> 0 | D35: ='Black Hills'!D8 -> 0 | E35: ='Black Hills'!E8 -> N/A | F35: ='Black Hills'!F8 -> 0 | G35: ='Black Hills'!G8 -> 0 | H35: ='Black Hills'!H8 -> N/A
B36: Campbell and Company | C36: ='Campbell & Co'!C8 -> 0 | D36: ='Campbell & Co'!D8 -> 0 | E36: ='Campbell & Co'!E8 -> N/A | F36: ='Campbell & Co'!F8 -> 0 | G36: ='Campbell & Co'!G8 -> 0 | H36: ='Campbell & Co'!H8 -> N/A
B37: Cassell Brothers | C37: ='Cassell Bros'!C8 -> 0 | D37: ='Cassell Bros'!D8 -> 0 | E37: ='Cassell Bros'!E8 -> N/A | F37: ='Cassell Bros'!F8 -> 0 | G37: ='Cassell Bros'!G8 -> 0 | H37: ='Cassell Bros'!H8 -> N/A
B38: Charles Stone Mechanical | C38: ='Charles Stone'!C8 -> 0 | D38: ='Charles Stone'!D8 -> 0 | E38: ='Charles Stone'!E8 -> N/A | F38: ='Charles Stone'!F8 -> 0 | G38: ='Charles Stone'!G8 -> 0 | H38: ='Charles Stone'!H8 -> N/A
B39: Dauenhauer Plumbing | C39: =Dauenhauer!C8 -> 0 | D39: =Dauenhauer!D8 -> 0 | E39: =Dauenhauer!E8 -> N/A | F39: =Dauenhauer!F8 -> 0 | G39: =Dauenhauer!G8 -> 0 | H39: =Dauenhauer!H8 -> N/A
B40: Fayette Heating & Air | C40: ='Fayette HA'!C8 -> 0 | D40: ='Fayette HA'!D8 -> 0 | E40: ='Fayette HA'!E8 -> N/A | F40: ='Fayette HA'!F8 -> 0 | G40: ='Fayette HA'!G8 -> 0 | H40: ='Fayette HA'!H8 -> N/A
B41: GAC Services | C41: ='GAC Services'!C8 -> 0 | D41: ='GAC Services'!D8 -> 0 | E41: ='GAC Services'!E8 -> N/A | F41: ='GAC Services'!F8 -> 0 | G41: ='GAC Services'!G8 -> 0 | H41: ='GAC Services'!H8 -> N/A
B42: Hunter Super Techs | C42: ='Hunter Super Techs'!C8 -> 0 | D42: ='Hunter Super Techs'!D8 -> 0 | E42: ='Hunter Super Techs'!E8 -> N/A | F42: ='Hunter Super Techs'!F8 -> 0 | G42: ='Hunter Super Techs'!G8 -> 0 | H42: ='Hunter Super Techs'!H8 -> N/A
...

Sheet Media Channel Summary
A1: MEDIA CHANNEL PERFORMANCE — AGENCY CAMPAIGN ASSESSMENT
A2: Focus: Direct (TV Lift), Display (Targeted Ads), Paid Video (OTT/CTV), Cross-network
A4: Direct (Broadcast TV Lift Proxy) — Sessions by Brand
B5: Brand | C5: FY 2024 | D5: FY 2025 | E5: YoY Δ% | F5: Jan 2025 | G5: Jan 2026 | H5: Jan YoY Δ%
B6: Anthony | C6: =Anthony!C25 -> 0 | D6: =Anthony!D25 -> 0 | E6: =Anthony!E25 -> N/A | F6: =Anthony!F25 -> 0 | G6: =Anthony!G25 -> 0 | H6: =Anthony!H25 -> N/A
B7: Anytime Plumbing, Heating & Cooling | C7: ='Anytime PHC'!C25 -> 0 | D7: ='Anytime PHC'!D25 -> 0 | E7: ='Anytime PHC'!E25 -> N/A | F7: ='Anytime PHC'!F25 -> 0 | G7: ='Anytime PHC'!G25 -> 0 | H7: ='Anytime PHC'!H25 -> N/A
B8: Apollo Home | C8: ='Apollo Home'!C25 -> 0 | D8: ='Apollo Home'!D25 -> 0 | E8: ='Apollo Home'!E25 -> N/A | F8: ='Apollo Home'!F25 -> 0 | G8: ='Apollo Home'!G25 -> 0 | H8: ='Apollo Home'!H25 -> N/A
B9: Arctic Air Conditioning | C9: ='Arctic Air'!C25 -> 0 | D9: ='Arctic Air'!D25 -> 0 | E9: ='Arctic Air'!E25 -> N/A | F9: ='Arctic Air'!F25 -> 0 | G9: ='Arctic Air'!G25 -> 0 | H9: ='Arctic Air'!H25 -> N/A
B10: Aztec Plumbing | C10: ='Aztec Plumbing'!C25 -> 0 | D10: ='Aztec Plumbing'!D25 -> 0 | E10: ='Aztec Plumbing'!E25 -> N/A | F10: ='Aztec Plumbing'!F25 -> 0 | G10: ='Aztec Plumbing'!G25 -> 0 | H10: ='Aztec Plumbing'!H25 -> N/A
B11: Bell Brothers | C11: ='Bell Brothers'!C25 -> 0 | D11: ='Bell Brothers'!D25 -> 0 | E11: ='Bell Brothers'!E25 -> N/A | F11: ='Bell Brothers'!F25 -> 0 | G11: ='Bell Brothers'!G25 -> 0 | H11: ='Bell Brothers'!H25 -> N/A
B12: Black Hills Inc | C12: ='Black Hills'!C25 -> 0 | D12: ='Black Hills'!D25 -> 0 | E12: ='Black Hills'!E25 -> N/A | F12: ='Black Hills'!F25 -> 0 | G12: ='Black Hills'!G25 -> 0 | H12: ='Black Hills'!H25 -> N/A
B13: Campbell and Company | C13: ='Campbell & Co'!C25 -> 0 | D13: ='Campbell & Co'!D25 -> 0 | E13: ='Campbell & Co'!E25 -> N/A | F13: ='Campbell & Co'!F25 -> 0 | G13: ='Campbell & Co'!G25 -> 0 | H13: ='Campbell & Co'!H25 -> N/A
B14: Cassell Brothers | C14: ='Cassell Bros'!C25 -> 0 | D14: ='Cassell Bros'!D25 -> 0 | E14: ='Cassell Bros'!E25 -> N/A | F14: ='Cassell Bros'!F25 -> 0 | G14: ='Cassell Bros'!G25 -> 0 | H14: ='Cassell Bros'!H25 -> N/A
B15: Charles Stone Mechanical | C15: ='Charles Stone'!C25 -> 0 | D15: ='Charles Stone'!D25 -> 0 | E15: ='Charles Stone'!E25 -> N/A | F15: ='Charles Stone'!F25 -> 0 | G15: ='Charles Stone'!G25 -> 0 | H15: ='Charles Stone'!H25 -> N/A
B16: Dauenhauer Plumbing | C16: =Dauenhauer!C25 -> 0 | D16: =Dauenhauer!D25 -> 0 | E16: =Dauenhauer!E25 -> N/A | F16: =Dauenhauer!F25 -> 0 | G16: =Dauenhauer!G25 -> 0 | H16: =Dauenhauer!H25 -> N/A
B17: Fayette Heating & Air | C17: ='Fayette HA'!C25 -> 0 | D17: ='Fayette HA'!D25 -> 0 | E17: ='Fayette HA'!E25 -> N/A | F17: ='Fayette HA'!F25 -> 0 | G17: ='Fayette HA'!G25 -> 0 | H17: ='Fayette HA'!H25 -> N/A
B18: GAC Services | C18: ='GAC Services'!C25 -> 0 | D18: ='GAC Services'!D25 -> 0 | E18: ='GAC Services'!E25 -> N/A | F18: ='GAC Services'!F25 -> 0 | G18: ='GAC Services'!G25 -> 0 | H18: ='GAC Services'!H25 -> N/A
B19: Hunter Super Techs | C19: ='Hunter Super Techs'!C25 -> 0 | D19: ='Hunter Super Techs'!D25 -> 0 | E19: ='Hunter Super Techs'!E25 -> N/A | F19: ='Hunter Super Techs'!F25 -> 0 | G19: ='Hunter Super Techs'!G25 -> 0 | H19: ='Hunter Super Techs'!H25 -> N/A
B20: LimRic | C20: =LimRic!C25 -> 0 | D20: =LimRic!D25 -> 0 | E20: =LimRic!E25 -> N/A | F20: =LimRic!F25 -> 0 | G20: =LimRic!G25 -> 0 | H20: =LimRic!H25 -> N/A
B21: Reliable Power Systems | C21: ='Reliable Power'!C25 -> 0 | D21: ='Reliable Power'!D25 -> 0 | E21: ='Reliable Power'!E25 -> N/A | F21: ='Reliable Power'!F25 -> 0 | G21: ='Reliable Power'!G25 -> 0 | H21: ='Reliable Power'!H25 -> N/A
B22: Roth Home | C22: ='Roth Home'!C25 -> 0 | D22: ='Roth Home'!D25 -> 0 | E22: ='Roth Home'!E25 -> N/A | F22: ='Roth Home'!F25 -> 0 | G22: ='Roth Home'!G25 -> 0 | H22: ='Roth Home'!H25 -> N/A
B23: Schaal Plumbing, Heating & Cooling | C23: ='Schaal PHC'!C25 -> 0 | D23: ='Schaal PHC'!D25 -> 0 | E23: ='Schaal PHC'!E25 -> N/A | F23: ='Schaal PHC'!F25 -> 0 | G23: ='Schaal PHC'!G25 -> 0 | H23: ='Schaal PHC'!H25 -> N/A
B24: Sunny Service | C24: ='Sunny Service'!C25 -> 0 | D24: ='Sunny Service'!D25 -> 0 | E24: ='Sunny Service'!E25 -> N/A | F24: ='Sunny Service'!F25 -> 0 | G24: ='Sunny Service'!G25 -> 0 | H24: ='Sunny Service'!H25 -> N/A
B25: Webb HVAC | C25: ='Webb HVAC'!C25 -> 0 | D25: ='Webb HVAC'!D25 -> 0 | E25: ='Webb HVAC'!E25 -> N/A | F25: ='Webb HVAC'!F25 -> 0 | G25: ='Webb HVAC'!G25 -> 0 | H25: ='Webb HVAC'!H25 -> N/A
A27: Display (Targeted Display Ads) — Sessions by Brand
B28: Brand | C28: FY 2024 | D28: FY 2025 | E28: YoY Δ% | F28: Jan 2025 | G28: Jan 2026 | H28: Jan YoY Δ%
B29: Anthony | C29: =Anthony!C28 -> 0 | D29: =Anthony!D28 -> 0 | E29: =Anthony!E28 -> N/A | F29: =Anthony!F28 -> 0 | G29: =Anthony!G28 -> 0 | H29: =Anthony!H28 -> N/A
B30: Anytime Plumbing, Heating & Cooling | C30: ='Anytime PHC'!C28 -> 0 | D30: ='Anytime PHC'!D28 -> 0 | E30: ='Anytime PHC'!E28 -> N/A | F30: ='Anytime PHC'!F28 -> 0 | G30: ='Anytime PHC'!G28 -> 0 | H30: ='Anytime PHC'!H28 -> N/A
B31: Apollo Home | C31: ='Apollo Home'!C28 -> 0 | D31: ='Apollo Home'!D28 -> 0 | E31: ='Apollo Home'!E28 -> N/A | F31: ='Apollo Home'!F28 -> 0 | G31: ='Apollo Home'!G28 -> 0 | H31: ='Apollo Home'!H28 -> N/A
B32: Arctic Air Conditioning | C32: ='Arctic Air'!C28 -> 0 | D32: ='Arctic Air'!D28 -> 0 | E32: ='Arctic Air'!E28 -> N/A | F32: ='Arctic Air'!F28 -> 0 | G32: ='Arctic Air'!G28 -> 0 | H32: ='Arctic Air'!H28 -> N/A
B33: Aztec Plumbing | C33: ='Aztec Plumbing'!C28 -> 0 | D33: ='Aztec Plumbing'!D28 -> 0 | E33: ='Aztec Plumbing'!E28 -> N/A | F33: ='Aztec Plumbing'!F28 -> 0 | G33: ='Aztec Plumbing'!G28 -> 0 | H33: ='Aztec Plumbing'!H28 -> N/A
B34: Bell Brothers | C34: ='Bell Brothers'!C28 -> 0 | D34: ='Bell Brothers'!D28 -> 0 | E34: ='Bell Brothers'!E28 -> N/A | F34: ='Bell Brothers'!F28 -> 0 | G34: ='Bell Brothers'!G28 -> 0 | H34: ='Bell Brothers'!H28 -> N/A
B35: Black Hills Inc | C35: ='Black Hills'!C28 -> 0 | D35: ='Black Hills'!D28 -> 0 | E35: ='Black Hills'!E28 -> N/A | F35: ='Black Hills'!F28 -> 0 | G35: ='Black Hills'!G28 -> 0 | H35: ='Black Hills'!H28 -> N/A
B36: Campbell and Company | C36: ='Campbell & Co'!C28 -> 0 | D36: ='Campbell & Co'!D28 -> 0 | E36: ='Campbell & Co'!E28 -> N/A | F36: ='Campbell & Co'!F28 -> 0 | G36: ='Campbell & Co'!G28 -> 0 | H36: ='Campbell & Co'!H28 -> N/A
B37: Cassell Brothers | C37: ='Cassell Bros'!C28 -> 0 | D37: ='Cassell Bros'!D28 -> 0 | E37: ='Cassell Bros'!E28 -> N/A | F37: ='Cassell Bros'!F28 -> 0 | G37: ='Cassell Bros'!G28 -> 0 | H37: ='Cassell Bros'!H28 -> N/A
B38: Charles Stone Mechanical | C38: ='Charles Stone'!C28 -> 0 | D38: ='Charles Stone'!D28 -> 0 | E38: ='Charles Stone'!E28 -> N/A | F38: ='Charles Stone'!F28 -> 0 | G38: ='Charles Stone'!G28 -> 0 | H38: ='Charles Stone'!H28 -> N/A
B39: Dauenhauer Plumbing | C39: =Dauenhauer!C28 -> 0 | D39: =Dauenhauer!D28 -> 0 | E39: =Dauenhauer!E28 -> N/A | F39: =Dauenhauer!F28 -> 0 | G39: =Dauenhauer!G28 -> 0 | H39: =Dauenhauer!H28 -> N/A
B40: Fayette Heating & Air | C40: ='Fayette HA'!C28 -> 0 | D40: ='Fayette HA'!D28 -> 0 | E40: ='Fayette HA'!E28 -> N/A | F40: ='Fayette HA'!F28 -> 0 | G40: ='Fayette HA'!G28 -> 0 | H40: ='Fayette HA'!H28 -> N/A
B41: GAC Services | C41: ='GAC Services'!C28 -> 0 | D41: ='GAC Services'!D28 -> 0 | E41: ='GAC Services'!E28 -> N/A | F41: ='GAC Services'!F28 -> 0 | G41: ='GAC Services'!G28 -> 0 | H41: ='GAC Services'!H28 -> N/A
B42: Hunter Super Techs | C42: ='Hunter Super Techs'!C28 -> 0 | D42: ='Hunter Super Techs'!D28 -> 0 | E42: ='Hunter Super Techs'!E28 -> N/A | F42: ='Hunter Super Techs'!F28 -> 0 | G42: ='Hunter Super Techs'!G28 -> 0 | H42: ='Hunter Super Techs'!H28 -> N/A
...

Sheet Anthony
A1: Anthony
A2: GA4 Account ID: 266746707
A4: SECTION 1: OVERVIEW METRICS
B5: Metric | C5: Full Year 2024 | D5: Full Year 2025 | E5: YoY Change % | F5: Jan 2025 | G5: Jan 2026 | H5: MoM Change %
B6: Traffic & Acquisition
B7: Total Users | E7: =IF(C7=0,"N/A",(D7-C7)/C7) -> N/A | H7: =IF(F7=0,"N/A",(G7-F7)/F7) -> N/A
B8: New Users | E8: =IF(C8=0,"N/A",(D8-C8)/C8) -> N/A | H8: =IF(F8=0,"N/A",(G8-F8)/F8) -> N/A
B9: Sessions | E9: =IF(C9=0,"N/A",(D9-C9)/C9) -> N/A | H9: =IF(F9=0,"N/A",(G9-F9)/F9) -> N/A
B10: Pageviews (Screen Views) | E10: =IF(C10=0,"N/A",(D10-C10)/C10) -> N/A | H10: =IF(F10=0,"N/A",(G10-F10)/F10) -> N/A
B11: Engagement
B12: Engagement Rate | E12: =IF(C12=0,"N/A",(D12-C12)/C12) -> N/A | H12: =IF(F12=0,"N/A",(G12-F12)/F12) -> N/A
B13: Avg. Session Duration (sec) | E13: =IF(C13=0,"N/A",(D13-C13)/C13) -> N/A | H13: =IF(F13=0,"N/A",(G13-F13)/F13) -> N/A
B14: Engaged Sessions per User | E14: =IF(C14=0,"N/A",(D14-C14)/C14) -> N/A | H14: =IF(F14=0,"N/A",(G14-F14)/F14) -> N/A
B15: Events Count | E15: =IF(C15=0,"N/A",(D15-C15)/C15) -> N/A | H15: =IF(F15=0,"N/A",(G15-F15)/F15) -> N/A
B16: Pages per Session | E16: =IF(C16=0,"N/A",(D16-C16)/C16) -> N/A | H16: =IF(F16=0,"N/A",(G16-F16)/F16) -> N/A
B17: Conversions
B18: Key Events (Conversions) | E18: =IF(C18=0,"N/A",(D18-C18)/C18) -> N/A | H18: =IF(F18=0,"N/A",(G18-F18)/F18) -> N/A
B19: User Conversion Rate | E19: =IF(C19=0,"N/A",(D19-C19)/C19) -> N/A | H19: =IF(F19=0,"N/A",(G19-F19)/F19) -> N/A
B20: Session Conversion Rate | E20: =IF(C20=0,"N/A",(D20-C20)/C20) -> N/A | H20: =IF(F20=0,"N/A",(G20-F20)/F20) -> N/A
A22: SECTION 2: TRAFFIC SOURCES (Sessions by Channel)
B23: Channel | C23: Full Year 2024 | D23: Full Year 2025 | E23: YoY Change % | F23: Jan 2025 | G23: Jan 2026 | H23: MoM Change %
B24: Direct | E24: =IF(C24=0,"N/A",(D24-C24)/C24) -> N/A | H24: =IF(F24=0,"N/A",(G24-F24)/F24) -> N/A
B25: Organic Search | E25: =IF(C25=0,"N/A",(D25-C25)/C25) -> N/A | H25: =IF(F25=0,"N/A",(G25-F25)/F25) -> N/A
B26: Paid Search | E26: =IF(C26=0,"N/A",(D26-C26)/C26) -> N/A | H26: =IF(F26=0,"N/A",(G26-F26)/F26) -> N/A
B27: Display | E27: =IF(C27=0,"N/A",(D27-C27)/C27) -> N/A | H27: =IF(F27=0,"N/A",(G27-F27)/F27) -> N/A
B28: Paid Video (OTT) | E28: =IF(C28=0,"N/A",(D28-C28)/C28) -> N/A | H28: =IF(F28=0,"N/A",(G28-F28)/F28) -> N/A
B29: Cross-network | E29: =IF(C29=0,"N/A",(D29-C29)/C29) -> N/A | H29: =IF(F29=0,"N/A",(G29-F29)/F29) -> N/A
B30: Social (Organic) | E30: =IF(C30=0,"N/A",(D30-C30)/C30) -> N/A | H30: =IF(F30=0,"N/A",(G30-F30)/F30) -> N/A
B31: Social (Paid) | E31: =IF(C31=0,"N/A",(D31-C31)/C31) -> N/A | H31: =IF(F31=0,"N/A",(G31-F31)/F31) -> N/A
B32: Referral | E32: =IF(C32=0,"N/A",(D32-C32)/C32) -> N/A | H32: =IF(F32=0,"N/A",(G32-F32)/F32) -> N/A
B33: Email | E33: =IF(C33=0,"N/A",(D33-C33)/C33) -> N/A | H33: =IF(F33=0,"N/A",(G33-F33)/F33) -> N/A
B34: Affiliates | E34: =IF(C34=0,"N/A",(D34-C34)/C34) -> N/A | H34: =IF(F34=0,"N/A",(G34-F34)/F34) -> N/A
B35: Audio | E35: =IF(C35=0,"N/A",(D35-C35)/C35) -> N/A | H35: =IF(F35=0,"N/A",(G35-F35)/F35) -> N/A
... B38: Other | E38: =IF(C38=0,"N/A",(D38-C38)/C38) -> N/A | H38: =IF(F38=0,"N/A",(G38-F38)/F38) -> N/A
B39: TOTAL SESSIONS | C39: =SUM(C24:C38) -> 0 | D39: =SUM(D24:D38) -> 0 | E39: =IF(C39=0,"N/A",(D39-C39)/C39) -> N/A | F39: =SUM(F24:F38) -> 0 | G39: =SUM(G24:G38) -> 0 | H39: =IF(F39=0,"N/A",(G39-F39)/F39) -> N/A
A41: SECTION 3: TOP REFERRAL SOURCES
B42: Referral Source | C42: FY 2024 Sessions | D42: FY 2025 Sessions | E42: YoY Change % | F42: Jan 2025 | G42: Jan 2026 | H42: MoM Change %
E43: =IF(C43=0,"N/A",(D43-C43)/C43) -> N/A | H43: =IF(F43=0,"N/A",(G43-F43)/F43) -> N/A
E44: =IF(C44=0,"N/A",(D44-C44)/C44) -> N/A | H44: =IF(F44=0,"N/A",(G44-F44)/F44) -> N/A
E45: =IF(C45=0,"N/A",(D45-C45)/C45) -> N/A | H45: =IF(F45=0,"N/A",(G45-F45)/F45) -> N/A
...

Sheet Anytime PHC
A1: Anytime Plumbing, Heating & Cooling
A2: GA4 Account ID: 48850300
A4: SECTION 1: OVERVIEW METRICS
B5: Metric | C5: Full Year 2024 | D5: Full Year 2025 | E5: YoY Change % | F5: Jan 2025 | G5: Jan 2026 | H5: MoM Change %
B6: Traffic & Acquisition
B7: Total Users | E7: =IF(C7=0,"N/A",(D7-C7)/C7) -> N/A | H7: =IF(F7=0,"N/A",(G7-F7)/F7) -> N/A
B8: New Users | E8: =IF(C8=0,"N/A",(D8-C8)/C8) -> N/A | H8: =IF(F8=0,"N/A",(G8-F8)/F8) -> N/A
B9: Sessions | E9: =IF(C9=0,"N/A",(D9-C9)/C9) -> N/A | H9: =IF(F9=0,"N/A",(G9-F9)/F9) -> N/A
B10: Pageviews (Screen Views) | E10: =IF(C10=0,"N/A",(D10-C10)/C10) -> N/A | H10: =IF(F10=0,"N/A",(G10-F10)/F10) -> N/A
B11: Engagement
B12: Engagement Rate | E12: =IF(C12=0,"N/A",(D12-C12)/C12) -> N/A | H12: =IF(F12=0,"N/A",(G12-F12)/F12) -> N/A
B13: Avg. Session Duration (sec) | E13: =IF(C13=0,"N/A",(D13-C13)/C13) -> N/A | H13: =IF(F13=0,"N/A",(G13-F13)/F13) -> N/A
B14: Engaged Sessions per User | E14: =IF(C14=0,"N/A",(D14-C14)/C14) -> N/A | H14: =IF(F14=0,"N/A",(G14-F14)/F14) -> N/A
B15: Events Count | E15: =IF(C15=0,"N/A",(D15-C15)/C15) -> N/A | H15: =IF(F15=0,"N/A",(G15-F15)/F15) -> N/A
B16: Pages per Session | E16: =IF(C16=0,"N/A",(D16-C16)/C16) -> N/A | H16: =IF(F16=0,"N/A",(G16-F16)/F16) -> N/A
B17: Conversions
B18: Key Events (Conversions) | E18: =IF(C18=0,"N/A",(D18-C18)/C18) -> N/A | H18: =IF(F18=0,"N/A",(G18-F18)/F18) -> N/A
B19: User Conversion Rate | E19: =IF(C19=0,"N/A",(D19-C19)/C19) -> N/A | H19: =IF(F19=0,"N/A",(G19-F19)/F19) -> N/A
B20: Session Conversion Rate | E20: =IF(C20=0,"N/A",(D20-C20)/C20) -> N/A | H20: =IF(F20=0,"N/A",(G20-F20)/F20) -> N/A
A22: SECTION 2: TRAFFIC SOURCES (Sessions by Channel)
B23: Channel | C23: Full Year 2024 | D23: Full Year 2025 | E23: YoY Change % | F23: Jan 2025 | G23: Jan 2026 | H23: MoM Change %
B24: Direct | E24: =IF(C24=0,"N/A",(D24-C24)/C24) -> N/A | H24: =IF(F24=0,"N/A",(G24-F24)/F24) -> N/A
B25: Organic Search | E25: =IF(C25=0,"N/A",(D25-C25)/C25) -> N/A | H25: =IF(F25=0,"N/A",(G25-F25)/F25) -> N/A
B26: Paid Search | E26: =IF(C26=0,"N/A",(D26-C26)/C26) -> N/A | H26: =IF(F26=0,"N/A",(G26-F26)/F26) -> N/A
B27: Display | E27: =IF(C27=0,"N/A",(D27-C27)/C27) -> N/A | H27: =IF(F27=0,"N/A",(G27-F27)/F27) -> N/A
B28: Paid Video (OTT) | E28: =IF(C28=0,"N/A",(D28-C28)/C28) -> N/A | H28: =IF(F28=0,"N/A",(G28-F28)/F28) -> N/A
B29: Cross-network | E29: =IF(C29=0,"N/A",(D29-C29)/C29) -> N/A | H29: =IF(F29=0,"N/A",(G29-F29)/F29) -> N/A
B30: Social (Organic) | E30: =IF(C30=0,"N/A",(D30-C30)/C30) -> N/A | H30: =IF(F30=0,"N/A",(G30-F30)/F30) -> N/A
B31: Social (Paid) | E31: =IF(C31=0,"N/A",(D31-C31)/C31) -> N/A | H31: =IF(F31=0,"N/A",(G31-F31)/F31) -> N/A
B32: Referral | E32: =IF(C32=0,"N/A",(D32-C32)/C32) -> N/A | H32: =IF(F32=0,"N/A",(G32-F32)/F32) -> N/A
B33: Email | E33: =IF(C33=0,"N/A",(D33-C33)/C33) -> N/A | H33: =IF(F33=0,"N/A",(G33-F33)/F33) -> N/A
B34: Affiliates | E34: =IF(C34=0,"N/A",(D34-C34)/C34) -> N/A | H34: =IF(F34=0,"N/A",(G34-F34)/F34) -> N/A
B35: Audio | E35: =IF(C35=0,"N/A",(D35-C35)/C35) -> N/A | H35: =IF(F35=0,"N/A",(G35-F35)/F35) -> N/A
... B38: Other | E38: =IF(C38=0,"N/A",(D38-C38)/C38) -> N/A | H38: =IF(F38=0,"N/A",(G38-F38)/F38) -> N/A
B39: TOTAL SESSIONS | C39: =SUM(C24:C38) -> 0 | D39: =SUM(D24:D38) -> 0 | E39: =IF(C39=0,"N/A",(D39-C39)/C39) -> N/A | F39: =SUM(F24:F38) -> 0 | G39: =SUM(G24:G38) -> 0 | H39: =IF(F39=0,"N/A",(G39-F39)/F39) -> N/A
A41: SECTION 3: TOP REFERRAL SOURCES
B42: Referral Source | C42: FY 2024 Sessions | D42: FY 2025 Sessions | E42: YoY Change % | F42: Jan 2025 | G42: Jan 2026 | H42: MoM Change %
E43: =IF(C43=0,"N/A",(D43-C43)/C43) -> N/A | H43: =IF(F43=0,"N/A",(G43-F43)/F43) -> N/A
E44: =IF(C44=0,"N/A",(D44-C44)/C44) -> N/A | H44: =IF(F44=0,"N/A",(G44-F44)/F44) -> N/A
E45: =IF(C45=0,"N/A",(D45-C45)/C45) -> N/A | H45: =IF(F45=0,"N/A",(G45-F45)/F45) -> N/A
...

Sheet Apollo Home
A1: Apollo Home
A2: GA4 Account ID: 11121287
A4: SECTION 1: OVERVIEW METRICS
B5: Metric | C5: Full Year 2024 | D5: Full Year 2025 | E5: YoY Change % | F5: Jan 2025 | G5: Jan 2026 | H5: MoM Change %
B6: Traffic & Acquisition
B7: Total Users | E7: =IF(C7=0,"N/A",(D7-C7)/C7) -> N/A | H7: =IF(F7=0,"N/A",(G7-F7)/F7) -> N/A
B8: New Users | E8: =IF(C8=0,"N/A",(D8-C8)/C8) -> N/A | H8: =IF(F8=0,"N/A",(G8-F8)/F8) -> N/A
B9: Sessions | E9: =IF(C9=0,"N/A",(D9-C9)/C9) -> N/A | H9: =IF(F9=0,"N/A",(G9-F9)/F9) -> N/A
B10: Pageviews (Screen Views) | E10: =IF(C10=0,"N/A",(D10-C10)/C10) -> N/A | H10: =IF(F10=0,"N/A",(G10-F10)/F10) -> N/A
B11: Engagement
B12: Engagement Rate | E12: =IF(C12=0,"N/A",(D12-C12)/C12) -> N/A | H12: =IF(F12=0,"N/A",(G12-F12)/F12) -> N/A
B13: Avg. Session Duration (sec) | E13: =IF(C13=0,"N/A",(D13-C13)/C13) -> N/A | H13: =IF(F13=0,"N/A",(G13-F13)/F13) -> N/A
B14: Engaged Sessions per User | E14: =IF(C14=0,"N/A",(D14-C14)/C14) -> N/A | H14: =IF(F14=0,"N/A",(G14-F14)/F14) -> N/A
B15: Events Count | E15: =IF(C15=0,"N/A",(D15-C15)/C15) -> N/A | H15: =IF(F15=0,"N/A",(G15-F15)/F15) -> N/A
B16: Pages per Session | E16: =IF(C16=0,"N/A",(D16-C16)/C16) -> N/A | H16: =IF(F16=0,"N/A",(G16-F16)/F16) -> N/A
B17: Conversions
B18: Key Events (Conversions) | E18: =IF(C18=0,"N/A",(D18-C18)/C18) -> N/A | H18: =IF(F18=0,"N/A",(G18-F18)/F18) -> N/A
B19: User Conversion Rate | E19: =IF(C19=0,"N/A",(D19-C19)/C19) -> N/A | H19: =IF(F19=0,"N/A",(G19-F19)/F19) -> N/A
B20: Session Conversion Rate | E20: =IF(C20=0,"N/A",(D20-C20)/C20) -> N/A | H20: =IF(F20=0,"N/A",(G20-F20)/F20) -> N/A
A22: SECTION 2: TRAFFIC SOURCES (Sessions by Channel)
B23: Channel | C23: Full Year 2024 | D23: Full Year 2025 | E23: YoY Change % | F23: Jan 2025 | G23: Jan 2026 | H23: MoM Change %
B24: Direct | E24: =IF(C24=0,"N/A",(D24-C24)/C24) -> N/A | H24: =IF(F24=0,"N/A",(G24-F24)/F24) -> N/A
B25: Organic Search | E25: =IF(C25=0,"N/A",(D25-C25)/C25) -> N/A | H25: =IF(F25=0,"N/A",(G25-F25)/F25) -> N/A
B26: Paid Search | E26: =IF(C26=0,"N/A",(D26-C26)/C26) -> N/A | H26: =IF(F26=0,"N/A",(G26-F26)/F26) -> N/A
B27: Display | E27: =IF(C27=0,"N/A",(D27-C27)/C27) -> N/A | H27: =IF(F27=0,"N/A",(G27-F27)/F27) -> N/A
B28: Paid Video (OTT) | E28: =IF(C28=0,"N/A",(D28-C28)/C28) -> N/A | H28: =IF(F28=0,"N/A",(G28-F28)/F28) -> N/A
B29: Cross-network | E29: =IF(C29=0,"N/A",(D29-C29)/C29) -> N/A | H29: =IF(F29=0,"N/A",(G29-F29)/F29) -> N/A
B30: Social (Organic) | E30: =IF(C30=0,"N/A",(D30-C30)/C30) -> N/A | H30: =IF(F30=0,"N/A",(G30-F30)/F30) -> N/A
B31: Social (Paid) | E31: =IF(C31=0,"N/A",(D31-C31)/C31) -> N/A | H31: =IF(F31=0,"N/A",(G31-F31)/F31) -> N/A
B32: Referral | E32: =IF(C32=0,"N/A",(D32-C32)/C32) -> N/A | H32: =IF(F32=0,"N/A",(G32-F32)/F32) -> N/A
B33: Email | E33: =IF(C33=0,"N/A",(D33-C33)/C33) -> N/A | H33: =IF(F33=0,"N/A",(G33-F33)/F33) -> N/A
B34: Affiliates | E34: =IF(C34=0,"N/A",(D34-C34)/C34) -> N/A | H34: =IF(F34=0,"N/A",(G34-F34)/F34) -> N/A
B35: Audio | E35: =IF(C35=0,"N/A",(D35-C35)/C35) -> N/A | H35: =IF(F35=0,"N/A",(G35-F35)/F35) -> N/A
... B38: Other | E38: =IF(C38=0,"N/A",(D38-C38)/C38) -> N/A | H38: =IF(F38=0,"N/A",(G38-F38)/F38) -> N/A
B39: TOTAL SESSIONS | C39: =SUM(C24:C38) -> 0 | D39: =SUM(D24:D38) -> 0 | E39: =IF(C39=0,"N/A",(D39-C39)/C39) -> N/A | F39: =SUM(F24:F38) -> 0 | G39: =SUM(G24:G38) -> 0 | H39: =IF(F39=0,"N/A",(G39-F39)/F39) -> N/A
A41: SECTION 3: TOP REFERRAL SOURCES
B42: Referral Source | C42: FY 2024 Sessions | D42: FY 2025 Sessions | E42: YoY Change % | F42: Jan 2025 | G42: Jan 2026 | H42: MoM Change %
E43: =IF(C43=0,"N/A",(D43-C43)/C43) -> N/A | H43: =IF(F43=0,"N/A",(G43-F43)/F43) -> N/A
E44: =IF(C44=0,"N/A",(D44-C44)/C44) -> N/A | H44: =IF(F44=0,"N/A",(G44-F44)/F44) -> N/A
E45: =IF(C45=0,"N/A",(D45-C45)/C45) -> N/A | H45: =IF(F45=0,"N/A",(G45-F45)/F45) -> N/A
...

Sheet Arctic Air
A1: Arctic Air Conditioning
A2: GA4 Account ID: 12778303
A4: SECTION 1: OVERVIEW METRICS
B5: Metric | C5: Full Year 2024 | D5: Full Year 2025 | E5: YoY Change % | F5: Jan 2025 | G5: Jan 2026 | H5: MoM Change %
B6: Traffic & Acquisition
B7: Total Users | E7: =IF(C7=0,"N/A",(D7-C7)/C7) -> N/A | H7: =IF(F7=0,"N/A",(G7-F7)/F7) -> N/A
B8: New Users | E8: =IF(C8=0,"N/A",(D8-C8)/C8) -> N/A | H8: =IF(F8=0,"N/A",(G8-F8)/F8) -> N/A
B9: Sessions | E9: =IF(C9=0,"N/A",(D9-C9)/C9) -> N/A | H9: =IF(F9=0,"N/A",(G9-F9)/F9) -> N/A
B10: Pageviews (Screen Views) | E10: =IF(C10=0,"N/A",(D10-C10)/C10) -> N/A | H10: =IF(F10=0,"N/A",(G10-F10)/F10) -> N/A
B11: Engagement
B12: Engagement Rate | E12: =IF(C12=0,"N/A",(D12-C12)/C12) -> N/A | H12: =IF(F12=0,"N/A",(G12-F12)/F12) -> N/A
B13: Avg. Session Duration (sec) | E13: =IF(C13=0,"N/A",(D13-C13)/C13) -> N/A | H13: =IF(F13=0,"N/A",(G13-F13)/F13) -> N/A
B14: Engaged Sessions per User | E14: =IF(C14=0,"N/A",(D14-C14)/C14) -> N/A | H14: =IF(F14=0,"N/A",(G14-F14)/F14) -> N/A
B15: Events Count | E15: =IF(C15=0,"N/A",(D15-C15)/C15) -> N/A | H15: =IF(F15=0,"N/A",(G15-F15)/F15) -> N/A
B16: Pages per Session | E16: =IF(C16=0,"N/A",(D16-C16)/C16) -> N/A | H16: =IF(F16=0,"N/A",(G16-F16)/F16) -> N/A
B17: Conversions
B18: Key Events (Conversions) | E18: =IF(C18=0,"N/A",(D18-C18)/C18) -> N/A | H18: =IF(F18=0,"N/A",(G18-F18)/F18) -> N/A
B19: User Conversion Rate | E19: =IF(C19=0,"N/A",(D19-C19)/C19) -> N/A | H19: =IF(F19=0,"N/A",(G19-F19)/F19) -> N/A
B20: Session Conversion Rate | E20: =IF(C20=0,"N/A",(D20-C20)/C20) -> N/A | H20: =IF(F20=0,"N/A",(G20-F20)/F20) -> N/A
A22: SECTION 2: TRAFFIC SOURCES (Sessions by Channel)
B23: Channel | C23: Full Year 2024 | D23: Full Year 2025 | E23: YoY Change % | F23: Jan 2025 | G23: Jan 2026 | H23: MoM Change %
B24: Direct | E24: =IF(C24=0,"N/A",(D24-C24)/C24) -> N/A | H24: =IF(F24=0,"N/A",(G24-F24)/F24) -> N/A
B25: Organic Search | E25: =IF(C25=0,"N/A",(D25-C25)/C25) -> N/A | H25: =IF(F25=0,"N/A",(G25-F25)/F25) -> N/A
B26: Paid Search | E26: =IF(C26=0,"N/A",(D26-C26)/C26) -> N/A | H26: =IF(F26=0,"N/A",(G26-F26)/F26) -> N/A
B27: Display | E27: =IF(C27=0,"N/A",(D27-C27)/C27) -> N/A | H27: =IF(F27=0,"N/A",(G27-F27)/F27) -> N/A
B28: Paid Video (OTT) | E28: =IF(C28=0,"N/A",(D28-C28)/C28) -> N/A | H28: =IF(F28=0,"N/A",(G28-F28)/F28) -> N/A
B29: Cross-network | E29: =IF(C29=0,"N/A",(D29-C29)/C29) -> N/A | H29: =IF(F29=0,"N/A",(G29-F29)/F29) -> N/A
B30: Social (Organic) | E30: =IF(C30=0,"N/A",(D30-C30)/C30) -> N/A | H30: =IF(F30=0,"N/A",(G30-F30)/F30) -> N/A
B31: Social (Paid) | E31: =IF(C31=0,"N/A",(D31-C31)/C31) -> N/A | H31: =IF(F31=0,"N/A",(G31-F31)/F31) -> N/A
B32: Referral | E32: =IF(C32=0,"N/A",(D32-C32)/C32) -> N/A | H32: =IF(F32=0,"N/A",(G32-F32)/F32) -> N/A
B33: Email | E33: =IF(C33=0,"N/A",(D33-C33)/C33) -> N/A | H33: =IF(F33=0,"N/A",(G33-F33)/F33) -> N/A
B34: Affiliates | E34: =IF(C34=0,"N/A",(D34-C34)/C34) -> N/A | H34: =IF(F34=0,"N/A",(G34-F34)/F34) -> N/A
B35: Audio | E35: =IF(C35=0,"N/A",(D35-C35)/C35) -> N/A | H35: =IF(F35=0,"N/A",(G35-F35)/F35) -> N/A
... B38: Other | E38: =IF(C38=0,"N/A",(D38-C38)/C38) -> N/A | H38: =IF(F38=0,"N/A",(G38-F38)/F38) -> N/A
B39: TOTAL SESSIONS | C39: =SUM(C24:C38) -> 0 | D39: =SUM(D24:D38) -> 0 | E39: =IF(C39=0,"N/A",(D39-C39)/C39) -> N/A | F39: =SUM(F24:F38) -> 0 | G39: =SUM(G24:G38) -> 0 | H39: =IF(F39=0,"N/A",(G39-F39)/F39) -> N/A
A41: SECTION 3: TOP REFERRAL SOURCES
B42: Referral Source | C42: FY 2024 Sessions | D42: FY 2025 Sessions | E42: YoY Change % | F42: Jan 2025 | G42: Jan 2026 | H42: MoM Change %
E43: =IF(C43=0,"N/A",(D43-C43)/C43) -> N/A | H43: =IF(F43=0,"N/A",(G43-F43)/F43) -> N/A
E44: =IF(C44=0,"N/A",(D44-C44)/C44) -> N/A | H44: =IF(F44=0,"N/A",(G44-F44)/F44) -> N/A
E45: =IF(C45=0,"N/A",(D45-C45)/C45) -> N/A | H45: =IF(F45=0,"N/A",(G45-F45)/F45) -> N/A
...

Sheet Aztec Plumbing
A1: Aztec Plumbing
A2: GA4 Account ID: —
A4: SECTION 1: OVERVIEW METRICS
B5: Metric | C5: Full Year 2024 | D5: Full Year 2025 | E5: YoY Change % | F5: Jan 2025 | G5: Jan 2026 | H5: MoM Change %
B6: Traffic & Acquisition
B7: Total Users | E7: =IF(C7=0,"N/A",(D7-C7)/C7) -> N/A | H7: =IF(F7=0,"N/A",(G7-F7)/F7) -> N/A
B8: New Users | E8: =IF(C8=0,"N/A",(D8-C8)/C8) -> N/A | H8: =IF(F8=0,"N/A",(G8-F8)/F8) -> N/A
B9: Sessions | E9: =IF(C9=0,"N/A",(D9-C9)/C9) -> N/A | H9: =IF(F9=0,"N/A",(G9-F9)/F9) -> N/A
B10: Pageviews (Screen Views) | E10: =IF(C10=0,"N/A",(D10-C10)/C10) -> N/A | H10: =IF(F10=0,"N/A",(G10-F10)/F10) -> N/A
B11: Engagement
B12: Engagement Rate | E12: =IF(C12=0,"N/A",(D12-C12)/C12) -> N/A | H12: =IF(F12=0,"N/A",(G12-F12)/F12) -> N/A
B13: Avg. Session Duration (sec) | E13: =IF(C13=0,"N/A",(D13-C13)/C13) -> N/A | H13: =IF(F13=0,"N/A",(G13-F13)/F13) -> N/A
B14: Engaged Sessions per User | E14: =IF(C14=0,"N/A",(D14-C14)/C14) -> N/A | H14: =IF(F14=0,"N/A",(G14-F14)/F14) -> N/A
B15: Events Count | E15: =IF(C15=0,"N/A",(D15-C15)/C15) -> N/A | H15: =IF(F15=0,"N/A",(G15-F15)/F15) -> N/A
B16: Pages per Session | E16: =IF(C16=0,"N/A",(D16-C16)/C16) -> N/A | H16: =IF(F16=0,"N/A",(G16-F16)/F16) -> N/A
B17: Conversions
B18: Key Events (Conversions) | E18: =IF(C18=0,"N/A",(D18-C18)/C18) -> N/A | H18: =IF(F18=0,"N/A",(G18-F18)/F18) -> N/A
B19: User Conversion Rate | E19: =IF(C19=0,"N/A",(D19-C19)/C19) -> N/A | H19: =IF(F19=0,"N/A",(G19-F19)/F19) -> N/A
B20: Session Conversion Rate | E20: =IF(C20=0,"N/A",(D20-C20)/C20) -> N/A | H20: =IF(F20=0,"N/A",(G20-F20)/F20) -> N/A
A22: SECTION 2: TRAFFIC SOURCES (Sessions by Channel)
B23: Channel | C23: Full Year 2024 | D23: Full Year 2025 | E23: YoY Change % | F23: Jan 2025 | G23: Jan 2026 | H23: MoM Change %
B24: Direct | E24: =IF(C24=0,"N/A",(D24-C24)/C24) -> N/A | H24: =IF(F24=0,"N/A",(G24-F24)/F24) -> N/A
B25: Organic Search | E25: =IF(C25=0,"N/A",(D25-C25)/C25) -> N/A | H25: =IF(F25=0,"N/A",(G25-F25)/F25) -> N/A
B26: Paid Search | E26: =IF(C26=0,"N/A",(D26-C26)/C26) -> N/A | H26: =IF(F26=0,"N/A",(G26-F26)/F26) -> N/A
B27: Display | E27: =IF(C27=0,"N/A",(D27-C27)/C27) -> N/A | H27: =IF(F27=0,"N/A",(G27-F27)/F27) -> N/A
B28: Paid Video (OTT) | E28: =IF(C28=0,"N/A",(D28-C28)/C28) -> N/A | H28: =IF(F28=0,"N/A",(G28-F28)/F28) -> N/A
B29: Cross-network | E29: =IF(C29=0,"N/A",(D29-C29)/C29) -> N/A | H29: =IF(F29=0,"N/A",(G29-F29)/F29) -> N/A
B30: Social (Organic) | E30: =IF(C30=0,"N/A",(D30-C30)/C30) -> N/A | H30: =IF(F30=0,"N/A",(G30-F30)/F30) -> N/A
B31: Social (Paid) | E31: =IF(C31=0,"N/A",(D31-C31)/C31) -> N/A | H31: =IF(F31=0,"N/A",(G31-F31)/F31) -> N/A
B32: Referral | E32: =IF(C32=0,"N/A",(D32-C32)/C32) -> N/A | H32: =IF(F32=0,"N/A",(G32-F32)/F32) -> N/A
B33: Email | E33: =IF(C33=0,"N/A",(D33-C33)/C33) -> N/A | H33: =IF(F33=0,"N/A",(G33-F33)/F33) -> N/A
B34: Affiliates | E34: =IF(C34=0,"N/A",(D34-C34)/C34) -> N/A | H34: =IF(F34=0,"N/A",(G34-F34)/F34) -> N/A
B35: Audio | E35: =IF(C35=0,"N/A",(D35-C35)/C35) -> N/A | H35: =IF(F35=0,"N/A",(G35-F35)/F35) -> N/A
... B38: Other | E38: =IF(C38=0,"N/A",(D38-C38)/C38) -> N/A | H38: =IF(F38=0,"N/A",(G38-F38)/F38) -> N/A
B39: TOTAL SESSIONS | C39: =SUM(C24:C38) -> 0 | D39: =SUM(D24:D38) -> 0 | E39: =IF(C39=0,"N/A",(D39-C39)/C39) -> N/A | F39: =SUM(F24:F38) -> 0 | G39: =SUM(G24:G38) -> 0 | H39: =IF(F39=0,"N/A",(G39-F39)/F39) -> N/A
A41: SECTION 3: TOP REFERRAL SOURCES
B42: Referral Source | C42: FY 2024 Sessions | D42: FY 2025 Sessions | E42: YoY Change % | F42: Jan 2025 | G42: Jan 2026 | H42: MoM Change %
E43: =IF(C43=0,"N/A",(D43-C43)/C43) -> N/A | H43: =IF(F43=0,"N/A",(G43-F43)/F43) -> N/A
E44: =IF(C44=0,"N/A",(D44-C44)/C44) -> N/A | H44: =IF(F44=0,"N/A",(G44-F44)/F44) -> N/A
E45: =IF(C45=0,"N/A",(D45-C45)/C45) -> N/A | H45: =IF(F45=0,"N/A",(G45-F45)/F45) -> N/A
...

Sheet Bell Brothers
A1: Bell Brothers
A2: GA4 Account ID: 262504860
A4: SECTION 1: OVERVIEW METRICS
B5: Metric | C5: Full Year 2024 | D5: Full Year 2025 | E5: YoY Change % | F5: Jan 2025 | G5: Jan 2026 | H5: MoM Change %
B6: Traffic & Acquisition
B7: Total Users | E7: =IF(C7=0,"N/A",(D7-C7)/C7) -> N/A | H7: =IF(F7=0,"N/A",(G7-F7)/F7) -> N/A
B8: New Users | E8: =IF(C8=0,"N/A",(D8-C8)/C8) -> N/A | H8: =IF(F8=0,"N/A",(G8-F8)/F8) -> N/A
B9: Sessions | E9: =IF(C9=0,"N/A",(D9-C9)/C9) -> N/A | H9: =IF(F9=0,"N/A",(G9-F9)/F9) -> N/A
B10: Pageviews (Screen Views) | E10: =IF(C10=0,"N/A",(D10-C10)/C10) -> N/A | H10: =IF(F10=0,"N/A",(G10-F10)/F10) -> N/A
B11: Engagement
B12: Engagement Rate | E12: =IF(C12=0,"N/A",(D12-C12)/C12) -> N/A | H12: =IF(F12=0,"N/A",(G12-F12)/F12) -> N/A
B13: Avg. Session Duration (sec) | E13: =IF(C13=0,"N/A",(D13-C13)/C13) -> N/A | H13: =IF(F13=0,"N/A",(G13-F13)/F13) -> N/A
B14: Engaged Sessions per User | E14: =IF(C14=0,"N/A",(D14-C14)/C14) -> N/A | H14: =IF(F14=0,"N/A",(G14-F14)/F14) -> N/A
B15: Events Count | E15: =IF(C15=0,"N/A",(D15-C15)/C15) -> N/A | H15: =IF(F15=0,"N/A",(G15-F15)/F15) -> N/A
B16: Pages per Session | E16: =IF(C16=0,"N/A",(D16-C16)/C16) -> N/A | H16: =IF(F16=0,"N/A",(G16-F16)/F16) -> N/A
B17: Conversions
B18: Key Events (Conversions) | E18: =IF(C18=0,"N/A",(D18-C18)/C18) -> N/A | H18: =IF(F18=0,"N/A",(G18-F18)/F18) -> N/A
B19: User Conversion Rate | E19: =IF(C19=0,"N/A",(D19-C19)/C19) -> N/A | H19: =IF(F19=0,"N/A",(G19-F19)/F19) -> N/A
B20: Session Conversion Rate | E20: =IF(C20=0,"N/A",(D20-C20)/C20) -> N/A | H20: =IF(F20=0,"N/A",(G20-F20)/F20) -> N/A
A22: SECTION 2: TRAFFIC SOURCES (Sessions by Channel)
B23: Channel | C23: Full Year 2024 | D23: Full Year 2025 | E23: YoY Change % | F23: Jan 2025 | G23: Jan 2026 | H23: MoM Change %
B24: Direct | E24: =IF(C24=0,"N/A",(D24-C24)/C24) -> N/A | H24: =IF(F24=0,"N/A",(G24-F24)/F24) -> N/A
B25: Organic Search | E25: =IF(C25=0,"N/A",(D25-C25)/C25) -> N/A | H25: =IF(F25=0,"N/A",(G25-F25)/F25) -> N/A
B26: Paid Search | E26: =IF(C26=0,"N/A",(D26-C26)/C26) -> N/A | H26: =IF(F26=0,"N/A",(G26-F26)/F26) -> N/A
B27: Display | E27: =IF(C27=0,"N/A",(D27-C27)/C27) -> N/A | H27: =IF(F27=0,"N/A",(G27-F27)/F27) -> N/A
B28: Paid Video (OTT) | E28: =IF(C28=0,"N/A",(D28-C28)/C28) -> N/A | H28: =IF(F28=0,"N/A",(G28-F28)/F28) -> N/A
B29: Cross-network | E29: =IF(C29=0,"N/A",(D29-C29)/C29) -> N/A | H29: =IF(F29=0,"N/A",(G29-F29)/F29) -> N/A
B30: Social (Organic) | E30: =IF(C30=0,"N/A",(D30-C30)/C30) -> N/A | H30: =IF(F30=0,"N/A",(G30-F30)/F30) -> N/A
B31: Social (Paid) | E31: =IF(C31=0,"N/A",(D31-C31)/C31) -> N/A | H31: =IF(F31=0,"N/A",(G31-F31)/F31) -> N/A
B32: Referral | E32: =IF(C32=0,"N/A",(D32-C32)/C32) -> N/A | H32: =IF(F32=0,"N/A",(G32-F32)/F32) -> N/A
B33: Email | E33: =IF(C33=0,"N/A",(D33-C33)/C33) -> N/A | H33: =IF(F33=0,"N/A",(G33-F33)/F33) -> N/A
B34: Affiliates | E34: =IF(C34=0,"N/A",(D34-C34)/C34) -> N/A | H34: =IF(F34=0,"N/A",(G34-F34)/F34) -> N/A
B35: Audio | E35: =IF(C35=0,"N/A",(D35-C35)/C35) -> N/A | H35: =IF(F35=0,"N/A",(G35-F35)/F35) -> N/A
... B38: Other | E38: =IF(C38=0,"N/A",(D38-C38)/C38) -> N/A | H38: =IF(F38=0,"N/A",(G38-F38)/F38) -> N/A
B39: TOTAL SESSIONS | C39: =SUM(C24:C38) -> 0 | D39: =SUM(D24:D38) -> 0 | E39: =IF(C39=0,"N/A",(D39-C39)/C39) -> N/A | F39: =SUM(F24:F38) -> 0 | G39: =SUM(G24:G38) -> 0 | H39: =IF(F39=0,"N/A",(G39-F39)/F39) -> N/A
A41: SECTION 3: TOP REFERRAL SOURCES
B42: Referral Source | C42: FY 2024 Sessions | D42: FY 2025 Sessions | E42: YoY Change % | F42: Jan 2025 | G42: Jan 2026 | H42: MoM Change %
E43: =IF(C43=0,"N/A",(D43-C43)/C43) -> N/A | H43: =IF(F43=0,"N/A",(G43-F43)/F43) -> N/A
E44: =IF(C44=0,"N/A",(D44-C44)/C44) -> N/A | H44: =IF(F44=0,"N/A",(G44-F44)/F44) -> N/A
E45: =IF(C45=0,"N/A",(D45-C45)/C45) -> N/A | H45: =IF(F45=0,"N/A",(G45-F45)/F45) -> N/A
...

Sheet Black Hills
A1: Black Hills Inc
A2: GA4 Account ID: 26334622
A4: SECTION 1: OVERVIEW METRICS
B5: Metric | C5: Full Year 2024 | D5: Full Year 2025 | E5: YoY Change % | F5: Jan 2025 | G5: Jan 2026 | H5: MoM Change %
B6: Traffic & Acquisition
B7: Total Users | E7: =IF(C7=0,"N/A",(D7-C7)/C7) -> N/A | H7: =IF(F7=0,"N/A",(G7-F7)/F7) -> N/A
B8: New Users | E8: =IF(C8=0,"N/A",(D8-C8)/C8) -> N/A | H8: =IF(F8=0,"N/A",(G8-F8)/F8) -> N/A
B9: Sessions | E9: =IF(C9=0,"N/A",(D9-C9)/C9) -> N/A | H9: =IF(F9=0,"N/A",(G9-F9)/F9) -> N/A
B10: Pageviews (Screen Views) | E10: =IF(C10=0,"N/A",(D10-C10)/C10) -> N/A | H10: =IF(F10=0,"N/A",(G10-F10)/F10) -> N/A
B11: Engagement
B12: Engagement Rate | E12: =IF(C12=0,"N/A",(D12-C12)/C12) -> N/A | H12: =IF(F12=0,"N/A",(G12-F12)/F12) -> N/A
B13: Avg. Session Duration (sec) | E13: =IF(C13=0,"N/A",(D13-C13)/C13) -> N/A | H13: =IF(F13=0,"N/A",(G13-F13)/F13) -> N/A
B14: Engaged Sessions per User | E14: =IF(C14=0,"N/A",(D14-C14)/C14) -> N/A | H14: =IF(F14=0,"N/A",(G14-F14)/F14) -> N/A
B15: Events Count | E15: =IF(C15=0,"N/A",(D15-C15)/C15) -> N/A | H15: =IF(F15=0,"N/A",(G15-F15)/F15) -> N/A
B16: Pages per Session | E16: =IF(C16=0,"N/A",(D16-C16)/C16) -> N/A | H16: =IF(F16=0,"N/A",(G16-F16)/F16) -> N/A
B17: Conversions
B18: Key Events (Conversions) | E18: =IF(C18=0,"N/A",(D18-C18)/C18) -> N/A | H18: =IF(F18=0,"N/A",(G18-F18)/F18) -> N/A
B19: User Conversion Rate | E19: =IF(C19=0,"N/A",(D19-C19)/C19) -> N/A | H19: =IF(F19=0,"N/A",(G19-F19)/F19) -> N/A
B20: Session Conversion Rate | E20: =IF(C20=0,"N/A",(D20-C20)/C20) -> N/A | H20: =IF(F20=0,"N/A",(G20-F20)/F20) -> N/A
A22: SECTION 2: TRAFFIC SOURCES (Sessions by Channel)
B23: Channel | C23: Full Year 2024 | D23: Full Year 2025 | E23: YoY Change % | F23: Jan 2025 | G23: Jan 2026 | H23: MoM Change %
B24: Direct | E24: =IF(C24=0,"N/A",(D24-C24)/C24) -> N/A | H24: =IF(F24=0,"N/A",(G24-F24)/F24) -> N/A
B25: Organic Search | E25: =IF(C25=0,"N/A",(D25-C25)/C25) -> N/A | H25: =IF(F25=0,"N/A",(G25-F25)/F25) -> N/A
B26: Paid Search | E26: =IF(C26=0,"N/A",(D26-C26)/C26) -> N/A | H26: =IF(F26=0,"N/A",(G26-F26)/F26) -> N/A
B27: Display | E27: =IF(C27=0,"N/A",(D27-C27)/C27) -> N/A | H27: =IF(F27=0,"N/A",(G27-F27)/F27) -> N/A
B28: Paid Video (OTT) | E28: =IF(C28=0,"N/A",(D28-C28)/C28) -> N/A | H28: =IF(F28=0,"N/A",(G28-F28)/F28) -> N/A
B29: Cross-network | E29: =IF(C29=0,"N/A",(D29-C29)/C29) -> N/A | H29: =IF(F29=0,"N/A",(G29-F29)/F29) -> N/A
B30: Social (Organic) | E30: =IF(C30=0,"N/A",(D30-C30)/C30) -> N/A | H30: =IF(F30=0,"N/A",(G30-F30)/F30) -> N/A
B31: Social (Paid) | E31: =IF(C31=0,"N/A",(D31-C31)/C31) -> N/A | H31: =IF(F31=0,"N/A",(G31-F31)/F31) -> N/A
B32: Referral | E32: =IF(C32=0,"N/A",(D32-C32)/C32) -> N/A | H32: =IF(F32=0,"N/A",(G32-F32)/F32) -> N/A
B33: Email | E33: =IF(C33=0,"N/A",(D33-C33)/C33) -> N/A | H33: =IF(F33=0,"N/A",(G33-F33)/F33) -> N/A
B34: Affiliates | E34: =IF(C34=0,"N/A",(D34-C34)/C34) -> N/A | H34: =IF(F34=0,"N/A",(G34-F34)/F34) -> N/A
B35: Audio | E35: =IF(C35=0,"N/A",(D35-C35)/C35) -> N/A | H35: =IF(F35=0,"N/A",(G35-F35)/F35) -> N/A
... B38: Other | E38: =IF(C38=0,"N/A",(D38-C38)/C38) -> N/A | H38: =IF(F38=0,"N/A",(G38-F38)/F38) -> N/A
B39: TOTAL SESSIONS | C39: =SUM(C24:C38) -> 0 | D39: =SUM(D24:D38) -> 0 | E39: =IF(C39=0,"N/A",(D39-C39)/C39) -> N/A | F39: =SUM(F24:F38) -> 0 | G39: =SUM(G24:G38) -> 0 | H39: =IF(F39=0,"N/A",(G39-F39)/F39) -> N/A
A41: SECTION 3: TOP REFERRAL SOURCES
B42: Referral Source | C42: FY 2024 Sessions | D42: FY 2025 Sessions | E42: YoY Change % | F42: Jan 2025 | G42: Jan 2026 | H42: MoM Change %
E43: =IF(C43=0,"N/A",(D43-C43)/C43) -> N/A | H43: =IF(F43=0,"N/A",(G43-F43)/F43) -> N/A
E44: =IF(C44=0,"N/A",(D44-C44)/C44) -> N/A | H44: =IF(F44=0,"N/A",(G44-F44)/F44) -> N/A
E45: =IF(C45=0,"N/A",(D45-C45)/C45) -> N/A | H45: =IF(F45=0,"N/A",(G45-F45)/F45) -> N/A
...

Sheet Campbell & Co
A1: Campbell and Company
A2: GA4 Account ID: 79041634
A4: SECTION 1: OVERVIEW METRICS
B5: Metric | C5: Full Year 2024 | D5: Full Year 2025 | E5: YoY Change % | F5: Jan 2025 | G5: Jan 2026 | H5: MoM Change %
B6: Traffic & Acquisition
B7: Total Users | E7: =IF(C7=0,"N/A",(D7-C7)/C7) -> N/A | H7: =IF(F7=0,"N/A",(G7-F7)/F7) -> N/A
B8: New Users | E8: =IF(C8=0,"N/A",(D8-C8)/C8) -> N/A | H8: =IF(F8=0,"N/A",(G8-F8)/F8) -> N/A
B9: Sessions | E9: =IF(C9=0,"N/A",(D9-C9)/C9) -> N/A | H9: =IF(F9=0,"N/A",(G9-F9)/F9) -> N/A
B10: Pageviews (Screen Views) | E10: =IF(C10=0,"N/A",(D10-C10)/C10) -> N/A | H10: =IF(F10=0,"N/A",(G10-F10)/F10) -> N/A
B11: Engagement
B12: Engagement Rate | E12: =IF(C12=0,"N/A",(D12-C12)/C12) -> N/A | H12: =IF(F12=0,"N/A",(G12-F12)/F12) -> N/A
B13: Avg. Session Duration (sec) | E13: =IF(C13=0,"N/A",(D13-C13)/C13) -> N/A | H13: =IF(F13=0,"N/A",(G13-F13)/F13) -> N/A
B14: Engaged Sessions per User | E14: =IF(C14=0,"N/A",(D14-C14)/C14) -> N/A | H14: =IF(F14=0,"N/A",(G14-F14)/F14) -> N/A
B15: Events Count | E15: =IF(C15=0,"N/A",(D15-C15)/C15) -> N/A | H15: =IF(F15=0,"N/A",(G15-F15)/F15) -> N/A
B16: Pages per Session | E16: =IF(C16=0,"N/A",(D16-C16)/C16) -> N/A | H16: =IF(F16=0,"N/A",(G16-F16)/F16) -> N/A
B17: Conversions
B18: Key Events (Conversions) | E18: =IF(C18=0,"N/A",(D18-C18)/C18) -> N/A | H18: =IF(F18=0,"N/A",(G18-F18)/F18) -> N/A
B19: User Conversion Rate | E19: =IF(C19=0,"N/A",(D19-C19)/C19) -> N/A | H19: =IF(F19=0,"N/A",(G19-F19)/F19) -> N/A
B20: Session Conversion Rate | E20: =IF(C20=0,"N/A",(D20-C20)/C20) -> N/A | H20: =IF(F20=0,"N/A",(G20-F20)/F20) -> N/A
A22: SECTION 2: TRAFFIC SOURCES (Sessions by Channel)
B23: Channel | C23: Full Year 2024 | D23: Full Year 2025 | E23: YoY Change % | F23: Jan 2025 | G23: Jan 2026 | H23: MoM Change %
B24: Direct | E24: =IF(C24=0,"N/A",(D24-C24)/C24) -> N/A | H24: =IF(F24=0,"N/A",(G24-F24)/F24) -> N/A
B25: Organic Search | E25: =IF(C25=0,"N/A",(D25-C25)/C25) -> N/A | H25: =IF(F25=0,"N/A",(G25-F25)/F25) -> N/A
B26: Paid Search | E26: =IF(C26=0,"N/A",(D26-C26)/C26) -> N/A | H26: =IF(F26=0,"N/A",(G26-F26)/F26) -> N/A
B27: Display | E27: =IF(C27=0,"N/A",(D27-C27)/C27) -> N/A | H27: =IF(F27=0,"N/A",(G27-F27)/F27) -> N/A
B28: Paid Video (OTT) | E28: =IF(C28=0,"N/A",(D28-C28)/C28) -> N/A | H28: =IF(F28=0,"N/A",(G28-F28)/F28) -> N/A
B29: Cross-network | E29: =IF(C29=0,"N/A",(D29-C29)/C29) -> N/A | H29: =IF(F29=0,"N/A",(G29-F29)/F29) -> N/A
B30: Social (Organic) | E30: =IF(C30=0,"N/A",(D30-C30)/C30) -> N/A | H30: =IF(F30=0,"N/A",(G30-F30)/F30) -> N/A
B31: Social (Paid) | E31: =IF(C31=0,"N/A",(D31-C31)/C31) -> N/A | H31: =IF(F31=0,"N/A",(G31-F31)/F31) -> N/A
B32: Referral | E32: =IF(C32=0,"N/A",(D32-C32)/C32) -> N/A | H32: =IF(F32=0,"N/A",(G32-F32)/F32) -> N/A
B33: Email | E33: =IF(C33=0,"N/A",(D33-C33)/C33) -> N/A | H33: =IF(F33=0,"N/A",(G33-F33)/F33) -> N/A
B34: Affiliates | E34: =IF(C34=0,"N/A",(D34-C34)/C34) -> N/A | H34: =IF(F34=0,"N/A",(G34-F34)/F34) -> N/A
B35: Audio | E35: =IF(C35=0,"N/A",(D35-C35)/C35) -> N/A | H35: =IF(F35=0,"N/A",(G35-F35)/F35) -> N/A
... B38: Other | E38: =IF(C38=0,"N/A",(D38-C38)/C38) -> N/A | H38: =IF(F38=0,"N/A",(G38-F38)/F38) -> N/A
B39: TOTAL SESSIONS | C39: =SUM(C24:C38) -> 0 | D39: =SUM(D24:D38) -> 0 | E39: =IF(C39=0,"N/A",(D39-C39)/C39) -> N/A | F39: =SUM(F24:F38) -> 0 | G39: =SUM(G24:G38) -> 0 | H39: =IF(F39=0,"N/A",(G39-F39)/F39) -> N/A
A41: SECTION 3: TOP REFERRAL SOURCES
B42: Referral Source | C42: FY 2024 Sessions | D42: FY 2025 Sessions | E42: YoY Change % | F42: Jan 2025 | G42: Jan 2026 | H42: MoM Change %
E43: =IF(C43=0,"N/A",(D43-C43)/C43) -> N/A | H43: =IF(F43=0,"N/A",(G43-F43)/F43) -> N/A
E44: =IF(C44=0,"N/A",(D44-C44)/C44) -> N/A | H44: =IF(F44=0,"N/A",(G44-F44)/F44) -> N/A
E45: =IF(C45=0,"N/A",(D45-C45)/C45) -> N/A | H45: =IF(F45=0,"N/A",(G45-F45)/F45) -> N/A
...

Sheet Cassell Bros
A1: Cassell Brothers
A2: GA4 Account ID: 104694076
A4: SECTION 1: OVERVIEW METRICS
B5: Metric | C5: Full Year 2024 | D5: Full Year 2025 | E5: YoY Change % | F5: Jan 2025 | G5: Jan 2026 | H5: MoM Change %
B6: Traffic & Acquisition
B7: Total Users | E7: =IF(C7=0,"N/A",(D7-C7)/C7) -> N/A | H7: =IF(F7=0,"N/A",(G7-F7)/F7) -> N/A
B8: New Users | E8: =IF(C8=0,"N/A",(D8-C8)/C8) -> N/A | H8: =IF(F8=0,"N/A",(G8-F8)/F8) -> N/A
B9: Sessions | E9: =IF(C9=0,"N/A",(D9-C9)/C9) -> N/A | H9: =IF(F9=0,"N/A",(G9-F9)/F9) -> N/A
B10: Pageviews (Screen Views) | E10: =IF(C10=0,"N/A",(D10-C10)/C10) -> N/A | H10: =IF(F10=0,"N/A",(G10-F10)/F10) -> N/A
B11: Engagement
B12: Engagement Rate | E12: =IF(C12=0,"N/A",(D12-C12)/C12) -> N/A | H12: =IF(F12=0,"N/A",(G12-F12)/F12) -> N/A
B13: Avg. Session Duration (sec) | E13: =IF(C13=0,"N/A",(D13-C13)/C13) -> N/A | H13: =IF(F13=0,"N/A",(G13-F13)/F13) -> N/A
B14: Engaged Sessions per User | E14: =IF(C14=0,"N/A",(D14-C14)/C14) -> N/A | H14: =IF(F14=0,"N/A",(G14-F14)/F14) -> N/A
B15: Events Count | E15: =IF(C15=0,"N/A",(D15-C15)/C15) -> N/A | H15: =IF(F15=0,"N/A",(G15-F15)/F15) -> N/A
B16: Pages per Session | E16: =IF(C16=0,"N/A",(D16-C16)/C16) -> N/A | H16: =IF(F16=0,"N/A",(G16-F16)/F16) -> N/A
B17: Conversions
B18: Key Events (Conversions) | E18: =IF(C18=0,"N/A",(D18-C18)/C18) -> N/A | H18: =IF(F18=0,"N/A",(G18-F18)/F18) -> N/A
B19: User Conversion Rate | E19: =IF(C19=0,"N/A",(D19-C19)/C19) -> N/A | H19: =IF(F19=0,"N/A",(G19-F19)/F19) -> N/A
B20: Session Conversion Rate | E20: =IF(C20=0,"N/A",(D20-C20)/C20) -> N/A | H20: =IF(F20=0,"N/A",(G20-F20)/F20) -> N/A
A22: SECTION 2: TRAFFIC SOURCES (Sessions by Channel)
B23: Channel | C23: Full Year 2024 | D23: Full Year 2025 | E23: YoY Change % | F23: Jan 2025 | G23: Jan 2026 | H23: MoM Change %
B24: Direct | E24: =IF(C24=0,"N/A",(D24-C24)/C24) -> N/A | H24: =IF(F24=0,"N/A",(G24-F24)/F24) -> N/A
B25: Organic Search | E25: =IF(C25=0,"N/A",(D25-C25)/C25) -> N/A | H25: =IF(F25=0,"N/A",(G25-F25)/F25) -> N/A
B26: Paid Search | E26: =IF(C26=0,"N/A",(D26-C26)/C26) -> N/A | H26: =IF(F26=0,"N/A",(G26-F26)/F26) -> N/A
B27: Display | E27: =IF(C27=0,"N/A",(D27-C27)/C27) -> N/A | H27: =IF(F27=0,"N/A",(G27-F27)/F27) -> N/A
B28: Paid Video (OTT) | E28: =IF(C28=0,"N/A",(D28-C28)/C28) -> N/A | H28: =IF(F28=0,"N/A",(G28-F28)/F28) -> N/A
B29: Cross-network | E29: =IF(C29=0,"N/A",(D29-C29)/C29) -> N/A | H29: =IF(F29=0,"N/A",(G29-F29)/F29) -> N/A
B30: Social (Organic) | E30: =IF(C30=0,"N/A",(D30-C30)/C30) -> N/A | H30: =IF(F30=0,"N/A",(G30-F30)/F30) -> N/A
B31: Social (Paid) | E31: =IF(C31=0,"N/A",(D31-C31)/C31) -> N/A | H31: =IF(F31=0,"N/A",(G31-F31)/F31) -> N/A
B32: Referral | E32: =IF(C32=0,"N/A",(D32-C32)/C32) -> N/A | H32: =IF(F32=0,"N/A",(G32-F32)/F32) -> N/A
B33: Email | E33: =IF(C33=0,"N/A",(D33-C33)/C33) -> N/A | H33: =IF(F33=0,"N/A",(G33-F33)/F33) -> N/A
B34: Affiliates | E34: =IF(C34=0,"N/A",(D34-C34)/C34) -> N/A | H34: =IF(F34=0,"N/A",(G34-F34)/F34) -> N/A
B35: Audio | E35: =IF(C35=0,"N/A",(D35-C35)/C35) -> N/A | H35: =IF(F35=0,"N/A",(G35-F35)/F35) -> N/A
... B38: Other | E38: =IF(C38=0,"N/A",(D38-C38)/C38) -> N/A | H38: =IF(F38=0,"N/A",(G38-F38)/F38) -> N/A
B39: TOTAL SESSIONS | C39: =SUM(C24:C38) -> 0 | D39: =SUM(D24:D38) -> 0 | E39: =IF(C39=0,"N/A",(D39-C39)/C39) -> N/A | F39: =SUM(F24:F38) -> 0 | G39: =SUM(G24:G38) -> 0 | H39: =IF(F39=0,"N/A",(G39-F39)/F39) -> N/A
A41: SECTION 3: TOP REFERRAL SOURCES
B42: Referral Source | C42: FY 2024 Sessions | D42: FY 2025 Sessions | E42: YoY Change % | F42: Jan 2025 | G42: Jan 2026 | H42: MoM Change %
E43: =IF(C43=0,"N/A",(D43-C43)/C43) -> N/A | H43: =IF(F43=0,"N/A",(G43-F43)/F43) -> N/A
E44: =IF(C44=0,"N/A",(D44-C44)/C44) -> N/A | H44: =IF(F44=0,"N/A",(G44-F44)/F44) -> N/A
E45: =IF(C45=0,"N/A",(D45-C45)/C45) -> N/A | H45: =IF(F45=0,"N/A",(G45-F45)/F45) -> N/A
...

Sheet Charles Stone
A1: Charles Stone Mechanical
A2: GA4 Account ID: 282662324
A4: SECTION 1: OVERVIEW METRICS
B5: Metric | C5: Full Year 2024 | D5: Full Year 2025 | E5: YoY Change % | F5: Jan 2025 | G5: Jan 2026 | H5: MoM Change %
B6: Traffic & Acquisition
B7: Total Users | E7: =IF(C7=0,"N/A",(D7-C7)/C7) -> N/A | H7: =IF(F7=0,"N/A",(G7-F7)/F7) -> N/A
B8: New Users | E8: =IF(C8=0,"N/A",(D8-C8)/C8) -> N/A | H8: =IF(F8=0,"N/A",(G8-F8)/F8) -> N/A
B9: Sessions | E9: =IF(C9=0,"N/A",(D9-C9)/C9) -> N/A | H9: =IF(F9=0,"N/A",(G9-F9)/F9) -> N/A
B10: Pageviews (Screen Views) | E10: =IF(C10=0,"N/A",(D10-C10)/C10) -> N/A | H10: =IF(F10=0,"N/A",(G10-F10)/F10) -> N/A
B11: Engagement
B12: Engagement Rate | E12: =IF(C12=0,"N/A",(D12-C12)/C12) -> N/A | H12: =IF(F12=0,"N/A",(G12-F12)/F12) -> N/A
B13: Avg. Session Duration (sec) | E13: =IF(C13=0,"N/A",(D13-C13)/C13) -> N/A | H13: =IF(F13=0,"N/A",(G13-F13)/F13) -> N/A
B14: Engaged Sessions per User | E14: =IF(C14=0,"N/A",(D14-C14)/C14) -> N/A | H14: =IF(F14=0,"N/A",(G14-F14)/F14) -> N/A
B15: Events Count | E15: =IF(C15=0,"N/A",(D15-C15)/C15) -> N/A | H15: =IF(F15=0,"N/A",(G15-F15)/F15) -> N/A
B16: Pages per Session | E16: =IF(C16=0,"N/A",(D16-C16)/C16) -> N/A | H16: =IF(F16=0,"N/A",(G16-F16)/F16) -> N/A
B17: Conversions
B18: Key Events (Conversions) | E18: =IF(C18=0,"N/A",(D18-C18)/C18) -> N/A | H18: =IF(F18=0,"N/A",(G18-F18)/F18) -> N/A
B19: User Conversion Rate | E19: =IF(C19=0,"N/A",(D19-C19)/C19) -> N/A | H19: =IF(F19=0,"N/A",(G19-F19)/F19) -> N/A
B20: Session Conversion Rate | E20: =IF(C20=0,"N/A",(D20-C20)/C20) -> N/A | H20: =IF(F20=0,"N/A",(G20-F20)/F20) -> N/A
A22: SECTION 2: TRAFFIC SOURCES (Sessions by Channel)
B23: Channel | C23: Full Year 2024 | D23: Full Year 2025 | E23: YoY Change % | F23: Jan 2025 | G23: Jan 2026 | H23: MoM Change %
B24: Direct | E24: =IF(C24=0,"N/A",(D24-C24)/C24) -> N/A | H24: =IF(F24=0,"N/A",(G24-F24)/F24) -> N/A
B25: Organic Search | E25: =IF(C25=0,"N/A",(D25-C25)/C25) -> N/A | H25: =IF(F25=0,"N/A",(G25-F25)/F25) -> N/A
B26: Paid Search | E26: =IF(C26=0,"N/A",(D26-C26)/C26) -> N/A | H26: =IF(F26=0,"N/A",(G26-F26)/F26) -> N/A
B27: Display | E27: =IF(C27=0,"N/A",(D27-C27)/C27) -> N/A | H27: =IF(F27=0,"N/A",(G27-F27)/F27) -> N/A
B28: Paid Video (OTT) | E28: =IF(C28=0,"N/A",(D28-C28)/C28) -> N/A | H28: =IF(F28=0,"N/A",(G28-F28)/F28) -> N/A
B29: Cross-network | E29: =IF(C29=0,"N/A",(D29-C29)/C29) -> N/A | H29: =IF(F29=0,"N/A",(G29-F29)/F29) -> N/A
B30: Social (Organic) | E30: =IF(C30=0,"N/A",(D30-C30)/C30) -> N/A | H30: =IF(F30=0,"N/A",(G30-F30)/F30) -> N/A
B31: Social (Paid) | E31: =IF(C31=0,"N/A",(D31-C31)/C31) -> N/A | H31: =IF(F31=0,"N/A",(G31-F31)/F31) -> N/A
B32: Referral | E32: =IF(C32=0,"N/A",(D32-C32)/C32) -> N/A | H32: =IF(F32=0,"N/A",(G32-F32)/F32) -> N/A
B33: Email | E33: =IF(C33=0,"N/A",(D33-C33)/C33) -> N/A | H33: =IF(F33=0,"N/A",(G33-F33)/F33) -> N/A
B34: Affiliates | E34: =IF(C34=0,"N/A",(D34-C34)/C34) -> N/A | H34: =IF(F34=0,"N/A",(G34-F34)/F34) -> N/A
B35: Audio | E35: =IF(C35=0,"N/A",(D35-C35)/C35) -> N/A | H35: =IF(F35=0,"N/A",(G35-F35)/F35) -> N/A
... B38: Other | E38: =IF(C38=0,"N/A",(D38-C38)/C38) -> N/A | H38: =IF(F38=0,"N/A",(G38-F38)/F38) -> N/A
B39: TOTAL SESSIONS | C39: =SUM(C24:C38) -> 0 | D39: =SUM(D24:D38) -> 0 | E39: =IF(C39=0,"N/A",(D39-C39)/C39) -> N/A | F39: =SUM(F24:F38) -> 0 | G39: =SUM(G24:G38) -> 0 | H39: =IF(F39=0,"N/A",(G39-F39)/F39) -> N/A
A41: SECTION 3: TOP REFERRAL SOURCES
B42: Referral Source | C42: FY 2024 Sessions | D42: FY 2025 Sessions | E42: YoY Change % | F42: Jan 2025 | G42: Jan 2026 | H42: MoM Change %
E43: =IF(C43=0,"N/A",(D43-C43)/C43) -> N/A | H43: =IF(F43=0,"N/A",(G43-F43)/F43) -> N/A
E44: =IF(C44=0,"N/A",(D44-C44)/C44) -> N/A | H44: =IF(F44=0,"N/A",(G44-F44)/F44) -> N/A
E45: =IF(C45=0,"N/A",(D45-C45)/C45) -> N/A | H45: =IF(F45=0,"N/A",(G45-F45)/F45) -> N/A
...

Sheet Dauenhauer
A1: Dauenhauer Plumbing
A2: GA4 Account ID: 39227647
A4: SECTION 1: OVERVIEW METRICS
B5: Metric | C5: Full Year 2024 | D5: Full Year 2025 | E5: YoY Change % | F5: Jan 2025 | G5: Jan 2026 | H5: MoM Change %
B6: Traffic & Acquisition
B7: Total Users | E7: =IF(C7=0,"N/A",(D7-C7)/C7) -> N/A | H7: =IF(F7=0,"N/A",(G7-F7)/F7) -> N/A
B8: New Users | E8: =IF(C8=0,"N/A",(D8-C8)/C8) -> N/A | H8: =IF(F8=0,"N/A",(G8-F8)/F8) -> N/A
B9: Sessions | E9: =IF(C9=0,"N/A",(D9-C9)/C9) -> N/A | H9: =IF(F9=0,"N/A",(G9-F9)/F9) -> N/A
B10: Pageviews (Screen Views) | E10: =IF(C10=0,"N/A",(D10-C10)/C10) -> N/A | H10: =IF(F10=0,"N/A",(G10-F10)/F10) -> N/A
B11: Engagement
B12: Engagement Rate | E12: =IF(C12=0,"N/A",(D12-C12)/C12) -> N/A | H12: =IF(F12=0,"N/A",(G12-F12)/F12) -> N/A
B13: Avg. Session Duration (sec) | E13: =IF(C13=0,"N/A",(D13-C13)/C13) -> N/A | H13: =IF(F13=0,"N/A",(G13-F13)/F13) -> N/A
B14: Engaged Sessions per User | E14: =IF(C14=0,"N/A",(D14-C14)/C14) -> N/A | H14: =IF(F14=0,"N/A",(G14-F14)/F14) -> N/A
B15: Events Count | E15: =IF(C15=0,"N/A",(D15-C15)/C15) -> N/A | H15: =IF(F15=0,"N/A",(G15-F15)/F15) -> N/A
B16: Pages per Session | E16: =IF(C16=0,"N/A",(D16-C16)/C16) -> N/A | H16: =IF(F16=0,"N/A",(G16-F16)/F16) -> N/A
B17: Conversions
B18: Key Events (Conversions) | E18: =IF(C18=0,"N/A",(D18-C18)/C18) -> N/A | H18: =IF(F18=0,"N/A",(G18-F18)/F18) -> N/A
B19: User Conversion Rate | E19: =IF(C19=0,"N/A",(D19-C19)/C19) -> N/A | H19: =IF(F19=0,"N/A",(G19-F19)/F19) -> N/A
B20: Session Conversion Rate | E20: =IF(C20=0,"N/A",(D20-C20)/C20) -> N/A | H20: =IF(F20=0,"N/A",(G20-F20)/F20) -> N/A
A22: SECTION 2: TRAFFIC SOURCES (Sessions by Channel)
B23: Channel | C23: Full Year 2024 | D23: Full Year 2025 | E23: YoY Change % | F23: Jan 2025 | G23: Jan 2026 | H23: MoM Change %
B24: Direct | E24: =IF(C24=0,"N/A",(D24-C24)/C24) -> N/A | H24: =IF(F24=0,"N/A",(G24-F24)/F24) -> N/A
B25: Organic Search | E25: =IF(C25=0,"N/A",(D25-C25)/C25) -> N/A | H25: =IF(F25=0,"N/A",(G25-F25)/F25) -> N/A
B26: Paid Search | E26: =IF(C26=0,"N/A",(D26-C26)/C26) -> N/A | H26: =IF(F26=0,"N/A",(G26-F26)/F26) -> N/A
B27: Display | E27: =IF(C27=0,"N/A",(D27-C27)/C27) -> N/A | H27: =IF(F27=0,"N/A",(G27-F27)/F27) -> N/A
B28: Paid Video (OTT) | E28: =IF(C28=0,"N/A",(D28-C28)/C28) -> N/A | H28: =IF(F28=0,"N/A",(G28-F28)/F28) -> N/A
B29: Cross-network | E29: =IF(C29=0,"N/A",(D29-C29)/C29) -> N/A | H29: =IF(F29=0,"N/A",(G29-F29)/F29) -> N/A
B30: Social (Organic) | E30: =IF(C30=0,"N/A",(D30-C30)/C30) -> N/A | H30: =IF(F30=0,"N/A",(G30-F30)/F30) -> N/A
B31: Social (Paid) | E31: =IF(C31=0,"N/A",(D31-C31)/C31) -> N/A | H31: =IF(F31=0,"N/A",(G31-F31)/F31) -> N/A
B32: Referral | E32: =IF(C32=0,"N/A",(D32-C32)/C32) -> N/A | H32: =IF(F32=0,"N/A",(G32-F32)/F32) -> N/A
B33: Email | E33: =IF(C33=0,"N/A",(D33-C33)/C33) -> N/A | H33: =IF(F33=0,"N/A",(G33-F33)/F33) -> N/A
B34: Affiliates | E34: =IF(C34=0,"N/A",(D34-C34)/C34) -> N/A | H34: =IF(F34=0,"N/A",(G34-F34)/F34) -> N/A
B35: Audio | E35: =IF(C35=0,"N/A",(D35-C35)/C35) -> N/A | H35: =IF(F35=0,"N/A",(G35-F35)/F35) -> N/A
... B38: Other | E38: =IF(C38=0,"N/A",(D38-C38)/C38) -> N/A | H38: =IF(F38=0,"N/A",(G38-F38)/F38) -> N/A
B39: TOTAL SESSIONS | C39: =SUM(C24:C38) -> 0 | D39: =SUM(D24:D38) -> 0 | E39: =IF(C39=0,"N/A",(D39-C39)/C39) -> N/A | F39: =SUM(F24:F38) -> 0 | G39: =SUM(G24:G38) -> 0 | H39: =IF(F39=0,"N/A",(G39-F39)/F39) -> N/A
A41: SECTION 3: TOP REFERRAL SOURCES
B42: Referral Source | C42: FY 2024 Sessions | D42: FY 2025 Sessions | E42: YoY Change % | F42: Jan 2025 | G42: Jan 2026 | H42: MoM Change %
E43: =IF(C43=0,"N/A",(D43-C43)/C43) -> N/A | H43: =IF(F43=0,"N/A",(G43-F43)/F43) -> N/A
E44: =IF(C44=0,"N/A",(D44-C44)/C44) -> N/A | H44: =IF(F44=0,"N/A",(G44-F44)/F44) -> N/A
E45: =IF(C45=0,"N/A",(D45-C45)/C45) -> N/A | H45: =IF(F45=0,"N/A",(G45-F45)/F45) -> N/A
...

Sheet Fayette HA
A1: Fayette Heating & Air
A2: GA4 Account ID: 262795854
A4: SECTION 1: OVERVIEW METRICS
